<?xml version="1.0"?>
<robot xmlns:xacro="http://www.ros.org/wiki/xacro" name="my_robot">

 <!-- Link -->
  <link name="base">
    <collision>
      <origin xyz="0 0 0.99" rpy="0 0 0"/>
      <geometry>
       <box size="0.9 0.7 1.9"/>
      </geometry>
    </collision>

    <visual>
      <origin xyz="0 0 0.99" rpy="0 0 0"/>
      <geometry>
        <box size="0.94 0.78 1.98"/>
      </geometry>
    </visual>
  </link>

  <link name="wheel_center">
    <collision>
      <origin xyz="0 0 0" rpy="0 0 0"/>
      <geometry>
        <cylinder length="0.05" radius="0.15"/>
      </geometry>
    </collision>

    <visual>
      <origin xyz="0 0 0" rpy="0 0 0"/>
      <geometry>
        <cylinder length="0.05" radius="0.15"/>
      </geometry>
    </visual>
  </link>

  <xacro:include filename="$(find gazebo_plugins)/test/multi_robot_scenario/xacro/laser/hokuyo.xacro" />
  <xacro:laser name="laser_horiz" parent="base" xyz="0.2325 0.0001 1.9201" rpy="-0.0012068 0.114646 -0.0015308" meshes="file://$(find gazebo_plugins)/test/multi_robot_scenario/meshes/laser"/>
  <xacro:laser name="laser_vert_bottom" parent="base" xyz="0.3158 -0.0021 0.5100" rpy="3.1355 -1.3045 0.0025" meshes="file://$(find gazebo_plugins)/test/multi_robot_scenario/meshes/laser"/>
  <xacro:laser name="laser_vert_top_right" parent="base" xyz="0.2978 -0.1450 1.8451" rpy="-1.1760 0.6313 -1.9377" meshes="file://$(find gazebo_plugins)/test/multi_robot_scenario/meshes/laser"/>
  <xacro:laser name="laser_vert_top_left" parent="base" xyz="0.2997 0.1531 1.8443" rpy="1.1780 0.6198 1.9560" meshes="file://$(find gazebo_plugins)/test/multi_robot_scenario/meshes/laser"/>

<!-- Joints -->
  <joint name="base_wheel_center" type="continuous">
      <parent link="base"/>
      <child link="wheel_center"/>
      <origin xyz="0.10 0.0 0.0" rpy="-1.57079632679 0 0"/>
      <limit effort="20.0" lower="0.0" upper="2.0" velocity="0.6"/>
      <axis xyz="0 0 1"/>
  </joint>

  <xacro:macro name="xacro_name" params="suffix reflect">
    <link name="wheel_${suffix}">
      <collision>
        <origin xyz="0 0 0" rpy="0 0 0"/>
        <geometry>
          <cylinder length="0.05" radius="0.2"/>
        </geometry>
      </collision>

      <visual>
        <origin xyz="0 0 0" rpy="0 0 0"/>
        <geometry>
          <cylinder length="0.05" radius="0.2"/>
        </geometry>
      </visual>
    </link>

    <joint name="base_wheel_${suffix}" type="continuous">
      <parent link="base"/>
      <child link="wheel_${suffix}"/>
      <origin xyz="-0.10 ${reflect*0.4} 0.0" rpy="-1.57079632679 0 0"/>
      <axis xyz="0 0 1"/>
      <limit effort="20.0" lower="0.0" upper="2.0" velocity="0.6"/>
    </joint>
  </xacro:macro>

  <xacro:xacro_name suffix="left" reflect="1" />
  <xacro:xacro_name suffix="right" reflect="-1" />
  
</robot>
